[32mINFO    [0m integration.test_exporter:test_exporter.py:202 Deploying self-signed-certificates
[32mINFO    [0m juju.model:model.py:2069 Deploying ch:amd64/jammy/self-signed-certificates-72
[32mINFO    [0m juju.model:model.py:2759 Waiting for model:
  self-signed-certificates/0 [allocating] waiting: installing agent
[32mINFO    [0m juju.model:model.py:2759 Waiting for model:
  self-signed-certificates/0 [idle] active: 
[32mINFO    [0m integration.test_exporter:test_exporter.py:213 Relating mysqlrouter with self-signed-certificates
[33mWARNING [0m juju.model:model.py:1558 relate is deprecated and will be removed. Use integrate instead.
[33mWARNING [0m urllib3.connectionpool:connectionpool.py:823 Retrying (Retry(total=2, connect=None, read=None, redirect=None, status=None)) after connection broken by 'NewConnectionError('<urllib3.connection.HTTPConnection object at 0x7f97e6749210>: Failed to establish a new connection: [Errno 111] Connection refused')': /metrics
[33mWARNING [0m urllib3.connectionpool:connectionpool.py:823 Retrying (Retry(total=1, connect=None, read=None, redirect=None, status=None)) after connection broken by 'NewConnectionError('<urllib3.connection.HTTPConnection object at 0x7f97e674bdc0>: Failed to establish a new connection: [Errno 111] Connection refused')': /metrics
[33mWARNING [0m urllib3.connectionpool:connectionpool.py:823 Retrying (Retry(total=0, connect=None, read=None, redirect=None, status=None)) after connection broken by 'NewConnectionError('<urllib3.connection.HTTPConnection object at 0x7f97e674aef0>: Failed to establish a new connection: [Errno 111] Connection refused')': /metrics
[32mINFO    [0m integration.test_exporter:test_exporter.py:239 Relating mysqlrouter with grafana agent
[33mWARNING [0m juju.model:model.py:1558 relate is deprecated and will be removed. Use integrate instead.
[33mWARNING [0m urllib3.connectionpool:connectionpool.py:823 Retrying (Retry(total=2, connect=None, read=None, redirect=None, status=None)) after connection broken by 'NewConnectionError('<urllib3.connection.HTTPConnection object at 0x7f97e70792d0>: Failed to establish a new connection: [Errno 111] Connection refused')': /metrics
[33mWARNING [0m urllib3.connectionpool:connectionpool.py:823 Retrying (Retry(total=1, connect=None, read=None, redirect=None, status=None)) after connection broken by 'NewConnectionError('<urllib3.connection.HTTPConnection object at 0x7f97e709ddb0>: Failed to establish a new connection: [Errno 111] Connection refused')': /metrics
[33mWARNING [0m urllib3.connectionpool:connectionpool.py:823 Retrying (Retry(total=0, connect=None, read=None, redirect=None, status=None)) after connection broken by 'NewConnectionError('<urllib3.connection.HTTPConnection object at 0x7f97e709cd60>: Failed to establish a new connection: [Errno 111] Connection refused')': /metrics
[32mINFO    [0m integration.test_exporter:test_exporter.py:266 Removing relation between mysqlrouter and grafana agent
[33mWARNING [0m urllib3.connectionpool:connectionpool.py:823 Retrying (Retry(total=2, connect=None, read=None, redirect=None, status=None)) after connection broken by 'NewConnectionError('<urllib3.connection.HTTPConnection object at 0x7f97e709fbb0>: Failed to establish a new connection: [Errno 111] Connection refused')': /metrics
[33mWARNING [0m urllib3.connectionpool:connectionpool.py:823 Retrying (Retry(total=1, connect=None, read=None, redirect=None, status=None)) after connection broken by 'NewConnectionError('<urllib3.connection.HTTPConnection object at 0x7f97e6d338e0>: Failed to establish a new connection: [Errno 111] Connection refused')': /metrics
[33mWARNING [0m urllib3.connectionpool:connectionpool.py:823 Retrying (Retry(total=0, connect=None, read=None, redirect=None, status=None)) after connection broken by 'NewConnectionError('<urllib3.connection.HTTPConnection object at 0x7f97e711d1b0>: Failed to establish a new connection: [Errno 111] Connection refused')': /metrics
[32mINFO    [0m integration.test_exporter:test_exporter.py:286 Removing relation between mysqlrouter and self-signed-certificates
[32mINFO    [0m pytest_operator.plugin:plugin.py:790 Model status:

Model  Controller          Cloud/Region        Version  SLA          Timestamp
test   microk8s-localhost  microk8s/localhost  3.4.3    unsupported  02:11:47Z

App                       Version                  Status   Scale  Charm                     Channel        Rev  Address         Exposed  Message
grafana-agent-k8s         0.35.2                   waiting      1  grafana-agent-k8s         latest/stable   68  10.152.183.183  no       installing agent
mysql-k8s                 8.0.36-0ubuntu0.22.04.1  active       1  mysql-k8s                 8.0/edge       150  10.152.183.115  no       
mysql-router-k8s          8.0.36-0ubuntu0.22.04.1  active       1  mysql-router-k8s                           0  10.152.183.70   no       
mysql-test-app            0.0.2                    active       1  mysql-test-app            latest/edge     38  10.152.183.142  no       Last written value=890
self-signed-certificates                           active       1  self-signed-certificates  latest/stable   72  10.152.183.74   no       

Unit                         Workload  Agent  Address      Ports  Message
grafana-agent-k8s/0*         blocked   idle   10.1.17.201         Missing ['grafana-cloud-config']|['grafana-dashboards-provider'] for grafana-dashboards-consumer; ['grafana-cloud-con...
mysql-k8s/0*                 active    idle   10.1.17.205         Primary
mysql-router-k8s/0*          active    idle   10.1.17.204         
mysql-test-app/0*            active    idle   10.1.17.203         Last written value=890
self-signed-certificates/0*  active    idle   10.1.17.206         

[32mINFO    [0m pytest_operator.plugin:plugin.py:796 Juju error logs:


[32mINFO    [0m pytest_operator.plugin:plugin.py:862 Forgetting main...