[32mINFO    [0m pytest_operator.plugin:plugin.py:675 Connecting to existing model microk8s-localhost:test on unspecified cloud
[33mWARNING [0m juju.client.connection:connection.py:927 unexpected facade UserSecretsDrain received from the controller
[33mWARNING [0m juju.client.connection:connection.py:927 unexpected facade UserSecretsManager received from the controller
[32mINFO    [0m integration.test_charm:test_charm.py:48 Deploying mysql, mysqlrouter and application
[32mINFO    [0m juju.model:model.py:2069 Deploying local:jammy/mysql-router-k8s-0
[32mINFO    [0m juju.model:model.py:2069 Deploying ch:amd64/jammy/mysql-test-app-58
[32mINFO    [0m juju.model:model.py:2069 Deploying ch:amd64/jammy/mysql-k8s-189
[32mINFO    [0m integration.test_charm:test_charm.py:79 Waiting for mysqlrouter to be in BlockedStatus
[32mINFO    [0m pytest_operator.plugin:plugin.py:790 Model status:

Model  Controller          Cloud/Region        Version  SLA          Timestamp
test   microk8s-localhost  microk8s/localhost  3.4.3    unsupported  02:38:28Z

App               Version                  Status   Scale  Charm             Channel      Rev  Address         Exposed  Message
mysql-k8s         8.0.37-0ubuntu0.22.04.3  active       3  mysql-k8s         8.0/edge     189  10.152.183.190  no       
mysql-router-k8s                           waiting      1  mysql-router-k8s                 0  10.152.183.101  no       installing agent
mysql-test-app    0.0.2                    waiting      1  mysql-test-app    latest/edge   58  10.152.183.149  no       installing agent

Unit                 Workload  Agent  Address      Ports  Message
mysql-k8s/0          active    idle   10.1.51.141         
mysql-k8s/1          active    idle   10.1.51.143         
mysql-k8s/2*         active    idle   10.1.51.142         Primary
mysql-router-k8s/0*  unknown   idle   10.1.51.136         
mysql-test-app/0*    waiting   idle   10.1.51.137         

[32mINFO    [0m pytest_operator.plugin:plugin.py:796 Juju error logs:

unit-mysql-k8s-0: 02:36:08 ERROR unit.mysql-k8s/0.juju-log Uncaught exception while in charm code:
Traceback (most recent call last):
  File "/var/lib/juju/agents/unit-mysql-k8s-0/charm/venv/websocket/_socket.py", line 118, in recv
    bytes_ = _recv()
  File "/var/lib/juju/agents/unit-mysql-k8s-0/charm/venv/websocket/_socket.py", line 97, in _recv
    return sock.recv(bufsize)
TimeoutError: timed out

During handling of the above exception, another exception occurred:

Traceback (most recent call last):
  File "/var/lib/juju/agents/unit-mysql-k8s-0/charm/venv/ops/pebble.py", line 2890, in exec
    control_ws = self._connect_websocket(task_id, 'control')
  File "/var/lib/juju/agents/unit-mysql-k8s-0/charm/venv/ops/pebble.py", line 2978, in _connect_websocket
    ws.connect(url, socket=sock)
  File "/var/lib/juju/agents/unit-mysql-k8s-0/charm/venv/websocket/_core.py", line 261, in connect
    self.handshake_response = handshake(self.sock, url, *addrs, **options)
  File "/var/lib/juju/agents/unit-mysql-k8s-0/charm/venv/websocket/_handshake.py", line 65, in handshake
    status, resp = _get_resp_headers(sock)
  File "/var/lib/juju/agents/unit-mysql-k8s-0/charm/venv/websocket/_handshake.py", line 141, in _get_resp_headers
    status, resp_headers, status_message = read_headers(sock)
  File "/var/lib/juju/agents/unit-mysql-k8s-0/charm/venv/websocket/_http.py", line 351, in read_headers
    line = recv_line(sock)
  File "/var/lib/juju/agents/unit-mysql-k8s-0/charm/venv/websocket/_socket.py", line 140, in recv_line
    c = recv(sock, 1)
  File "/var/lib/juju/agents/unit-mysql-k8s-0/charm/venv/websocket/_socket.py", line 120, in recv
    raise WebSocketTimeoutException("Connection timed out")
websocket._exceptions.WebSocketTimeoutException: Connection timed out

The above exception was the direct cause of the following exception:

Traceback (most recent call last):
  File "/var/lib/juju/agents/unit-mysql-k8s-0/charm/./src/charm.py", line 888, in <module>
    main(MySQLOperatorCharm)
  File "/var/lib/juju/agents/unit-mysql-k8s-0/charm/venv/ops/main.py", line 551, in main
    manager.run()
  File "/var/lib/juju/agents/unit-mysql-k8s-0/charm/venv/ops/main.py", line 530, in run
    self._emit()
  File "/var/lib/juju/agents/unit-mysql-k8s-0/charm/venv/ops/main.py", line 519, in _emit
    _emit_charm_event(self.charm, self.dispatcher.event_name)
  File "/var/lib/juju/agents/unit-mysql-k8s-0/charm/venv/ops/main.py", line 147, in _emit_charm_event
    event_to_emit.emit(*args, **kwargs)
  File "/var/lib/juju/agents/unit-mysql-k8s-0/charm/venv/ops/framework.py", line 348, in emit
    framework._emit(event)
  File "/var/lib/juju/agents/unit-mysql-k8s-0/charm/venv/ops/framework.py", line 860, in _emit
    self._reemit(event_path)
  File "/var/lib/juju/agents/unit-mysql-k8s-0/charm/venv/ops/framework.py", line 950, in _reemit
    custom_handler(event)
  File "/var/lib/juju/agents/unit-mysql-k8s-0/charm/lib/charms/tempo_k8s/v1/charm_tracing.py", line 735, in wrapped_function
    return callable(*args, **kwargs)  # type: ignore
  File "/var/lib/juju/agents/unit-mysql-k8s-0/charm/src/rotate_mysql_logs.py", line 56, in _rotate_mysql_logs
    self.charm._mysql._execute_commands(["logrotate", "-f", LOG_ROTATE_CONFIG_FILE])
  File "/var/lib/juju/agents/unit-mysql-k8s-0/charm/lib/charms/tempo_k8s/v1/charm_tracing.py", line 735, in wrapped_function
    return callable(*args, **kwargs)  # type: ignore
  File "/var/lib/juju/agents/unit-mysql-k8s-0/charm/src/mysql_k8s_helpers.py", line 559, in _execute_commands
    process = self.container.exec(
  File "/var/lib/juju/agents/unit-mysql-k8s-0/charm/venv/ops/model.py", line 2872, in exec
    return self._pebble.exec(
  File "/var/lib/juju/agents/unit-mysql-k8s-0/charm/venv/ops/pebble.py", line 2899, in exec
    raise ChangeError(change.err, change) from e
ops.pebble.ChangeError: cannot perform the following tasks:
- exec command "logrotate" (exec 545: timeout waiting for websocket connections: context deadline exceeded)
----- Logs from task 0 -----
2024-09-10T02:36:08Z ERROR exec 545: timeout waiting for websocket connections: context deadline exceeded
-----

[32mINFO    [0m pytest_operator.plugin:plugin.py:862 Forgetting main...
[31m[1mERROR   [0m websockets.client:protocol.py:1015 data transfer failed
Traceback (most recent call last):
  File "/home/runner/work/mysql-router-k8s-operator/mysql-router-k8s-operator/.tox/integration/lib/python3.10/site-packages/websockets/legacy/protocol.py", line 959, in transfer_data
    message = await self.read_message()
  File "/home/runner/work/mysql-router-k8s-operator/mysql-router-k8s-operator/.tox/integration/lib/python3.10/site-packages/websockets/legacy/protocol.py", line 1029, in read_message
    frame = await self.read_data_frame(max_size=self.max_size)
  File "/home/runner/work/mysql-router-k8s-operator/mysql-router-k8s-operator/.tox/integration/lib/python3.10/site-packages/websockets/legacy/protocol.py", line 1104, in read_data_frame
    frame = await self.read_frame(max_size)
  File "/home/runner/work/mysql-router-k8s-operator/mysql-router-k8s-operator/.tox/integration/lib/python3.10/site-packages/websockets/legacy/protocol.py", line 1161, in read_frame
    frame = await Frame.read(
  File "/home/runner/work/mysql-router-k8s-operator/mysql-router-k8s-operator/.tox/integration/lib/python3.10/site-packages/websockets/legacy/framing.py", line 68, in read
    data = await reader(2)
  File "/usr/lib/python3.10/asyncio/streams.py", line 708, in readexactly
    await self._wait_for_data('readexactly')
  File "/usr/lib/python3.10/asyncio/streams.py", line 501, in _wait_for_data
    await self._waiter
  File "/usr/lib/python3.10/asyncio/selector_events.py", line 924, in write
    n = self._sock.send(data)
OSError: [Errno 9] Bad file descriptor