[32mINFO    [0m pytest_operator.plugin:plugin.py:790 Model status:

Model  Controller          Cloud/Region        Version  SLA          Timestamp
test   microk8s-localhost  microk8s/localhost  3.4.3    unsupported  02:43:18Z

App                       Version                  Status   Scale  Charm                     Channel        Rev  Address         Exposed  Message
data-integrator                                    waiting      1  data-integrator           latest/edge     72  10.152.183.129  no       installing agent
mysql-k8s                 8.0.37-0ubuntu0.22.04.3  active       3  mysql-k8s                 8.0/edge       206  10.152.183.155  no       
mysql-router-k8s                                   waiting      1  mysql-router-k8s                           0  10.152.183.130  no       installing agent
mysql-test-app            0.0.2                    waiting      1  mysql-test-app            latest/edge     63  10.152.183.54   no       installing agent
self-signed-certificates                           active       1  self-signed-certificates  latest/stable  155  10.152.183.148  no       

Unit                         Workload  Agent      Address      Ports  Message
data-integrator/0*           blocked   idle       10.1.50.202         Please relate the data-integrator with the desired product
mysql-k8s/0*                 active    executing  10.1.50.208         Primary
mysql-k8s/1                  active    executing  10.1.50.209         
mysql-k8s/2                  active    executing  10.1.50.207         
mysql-router-k8s/0*          unknown   idle       10.1.50.200         
mysql-test-app/0*            waiting   idle       10.1.50.203         
self-signed-certificates/0*  active    idle       10.1.50.201         

[32mINFO    [0m pytest_operator.plugin:plugin.py:796 Juju error logs:

unit-mysql-k8s-0: 02:37:49 ERROR unit.mysql-k8s/0.juju-log Failed to get cluster status for cluster-4432ca3c655ba40e4e899a312ae5d3b1

[32mINFO    [0m pytest_operator.plugin:plugin.py:862 Forgetting main...
[31m[1mERROR   [0m websockets.client:protocol.py:1015 data transfer failed
Traceback (most recent call last):
  File "/home/runner/work/mysql-router-k8s-operator/mysql-router-k8s-operator/.tox/integration/lib/python3.10/site-packages/websockets/legacy/protocol.py", line 959, in transfer_data
    message = await self.read_message()
  File "/home/runner/work/mysql-router-k8s-operator/mysql-router-k8s-operator/.tox/integration/lib/python3.10/site-packages/websockets/legacy/protocol.py", line 1029, in read_message
    frame = await self.read_data_frame(max_size=self.max_size)
  File "/home/runner/work/mysql-router-k8s-operator/mysql-router-k8s-operator/.tox/integration/lib/python3.10/site-packages/websockets/legacy/protocol.py", line 1104, in read_data_frame
    frame = await self.read_frame(max_size)
  File "/home/runner/work/mysql-router-k8s-operator/mysql-router-k8s-operator/.tox/integration/lib/python3.10/site-packages/websockets/legacy/protocol.py", line 1161, in read_frame
    frame = await Frame.read(
  File "/home/runner/work/mysql-router-k8s-operator/mysql-router-k8s-operator/.tox/integration/lib/python3.10/site-packages/websockets/legacy/framing.py", line 68, in read
    data = await reader(2)
  File "/usr/lib/python3.10/asyncio/streams.py", line 708, in readexactly
    await self._wait_for_data('readexactly')
  File "/usr/lib/python3.10/asyncio/streams.py", line 501, in _wait_for_data
    await self._waiter
  File "/usr/lib/python3.10/asyncio/selector_events.py", line 924, in write
    n = self._sock.send(data)
OSError: [Errno 9] Bad file descriptor