[32mINFO    [0m pytest_operator.plugin:plugin.py:790 Model status:

Model  Controller          Cloud/Region        Version  SLA          Timestamp
test   microk8s-localhost  microk8s/localhost  3.4.3    unsupported  02:11:22Z

App                       Version  Status   Scale  Charm                     Channel        Rev  Address         Exposed  Message
data-integrator                    waiting      1  data-integrator           latest/edge     35  10.152.183.217  no       installing agent
mysql-k8s                          error      0/3  mysql-k8s                 8.0/edge       160  10.152.183.54   no       create Pod mysql-k8s-2 in StatefulSet mysql-k8s failed error: failed to create PVC mysql-k8s-database-aacbcffb-mysql-...
mysql-router-k8s                   waiting    0/1  mysql-router-k8s                           0  10.152.183.151  no       installing agent
mysql-test-app            0.0.2    waiting      1  mysql-test-app            latest/edge     46  10.152.183.150  no       installing agent
self-signed-certificates           active       1  self-signed-certificates  latest/stable  155  10.152.183.52   no       

Unit                         Workload  Agent       Address      Ports  Message
data-integrator/0*           blocked   idle        10.1.48.205         Please relate the data-integrator with the desired product
mysql-k8s/0                  waiting   allocating                      agent initialising
mysql-k8s/1                  waiting   allocating                      agent initialising
mysql-k8s/2*                 waiting   allocating                      agent initialising
mysql-router-k8s/0*          waiting   allocating  10.1.48.206         agent initialising
mysql-test-app/0*            waiting   idle        10.1.48.200         
self-signed-certificates/0*  active    idle        10.1.48.201         

[32mINFO    [0m pytest_operator.plugin:plugin.py:796 Juju error logs:


[32mINFO    [0m pytest_operator.plugin:plugin.py:862 Forgetting main...
[31m[1mERROR   [0m websockets.client:protocol.py:1015 data transfer failed
Traceback (most recent call last):
  File "/home/runner/work/mysql-router-k8s-operator/mysql-router-k8s-operator/.tox/integration/lib/python3.10/site-packages/websockets/legacy/protocol.py", line 959, in transfer_data
    message = await self.read_message()
  File "/home/runner/work/mysql-router-k8s-operator/mysql-router-k8s-operator/.tox/integration/lib/python3.10/site-packages/websockets/legacy/protocol.py", line 1029, in read_message
    frame = await self.read_data_frame(max_size=self.max_size)
  File "/home/runner/work/mysql-router-k8s-operator/mysql-router-k8s-operator/.tox/integration/lib/python3.10/site-packages/websockets/legacy/protocol.py", line 1104, in read_data_frame
    frame = await self.read_frame(max_size)
  File "/home/runner/work/mysql-router-k8s-operator/mysql-router-k8s-operator/.tox/integration/lib/python3.10/site-packages/websockets/legacy/protocol.py", line 1161, in read_frame
    frame = await Frame.read(
  File "/home/runner/work/mysql-router-k8s-operator/mysql-router-k8s-operator/.tox/integration/lib/python3.10/site-packages/websockets/legacy/framing.py", line 68, in read
    data = await reader(2)
  File "/usr/lib/python3.10/asyncio/streams.py", line 708, in readexactly
    await self._wait_for_data('readexactly')
  File "/usr/lib/python3.10/asyncio/streams.py", line 501, in _wait_for_data
    await self._waiter
  File "/usr/lib/python3.10/asyncio/selector_events.py", line 924, in write
    n = self._sock.send(data)
OSError: [Errno 9] Bad file descriptor