[32mINFO    [0m pytest_operator.plugin:plugin.py:675 Connecting to existing model microk8s-localhost:test on unspecified cloud
[33mWARNING [0m juju.client.connection:connection.py:927 unexpected facade UserSecretsDrain received from the controller
[33mWARNING [0m juju.client.connection:connection.py:927 unexpected facade UserSecretsManager received from the controller
[32mINFO    [0m integration.test_log_rotation:test_log_rotation.py:49 Deploying mysql, mysqlrouter and application
[32mINFO    [0m juju.model:model.py:2069 Deploying local:jammy/mysql-router-k8s-0
[32mINFO    [0m juju.model:model.py:2069 Deploying ch:amd64/jammy/mysql-test-app-63
[32mINFO    [0m juju.model:model.py:2069 Deploying ch:amd64/jammy/mysql-k8s-197
[32mINFO    [0m integration.test_log_rotation:test_log_rotation.py:80 Waiting for mysqlrouter to be in BlockedStatus
[32mINFO    [0m pytest_operator.plugin:plugin.py:790 Model status:

Model  Controller          Cloud/Region        Version  SLA          Timestamp
test   microk8s-localhost  microk8s/localhost  3.4.3    unsupported  02:38:48Z

App               Version                  Status   Scale  Charm             Channel      Rev  Address         Exposed  Message
mysql-k8s         8.0.37-0ubuntu0.22.04.3  active       3  mysql-k8s         8.0/edge     197  10.152.183.31   no       
mysql-router-k8s                           waiting      1  mysql-router-k8s                 0  10.152.183.237  no       installing agent
mysql-test-app    0.0.2                    waiting      1  mysql-test-app    latest/edge   63  10.152.183.72   no       installing agent

Unit                 Workload  Agent  Address       Ports  Message
mysql-k8s/0          active    idle   10.1.208.205         
mysql-k8s/1          active    idle   10.1.208.207         
mysql-k8s/2*         active    idle   10.1.208.206         Primary
mysql-router-k8s/0*  unknown   idle   10.1.208.200         
mysql-test-app/0*    waiting   idle   10.1.208.201         

[32mINFO    [0m pytest_operator.plugin:plugin.py:796 Juju error logs:


[32mINFO    [0m pytest_operator.plugin:plugin.py:862 Forgetting main...
[1m[31mERROR   [0m websockets.client:protocol.py:1015 data transfer failed
Traceback (most recent call last):
  File "/home/runner/work/mysql-router-k8s-operator/mysql-router-k8s-operator/.tox/integration/lib/python3.10/site-packages/websockets/legacy/protocol.py", line 959, in transfer_data
    message = await self.read_message()
  File "/home/runner/work/mysql-router-k8s-operator/mysql-router-k8s-operator/.tox/integration/lib/python3.10/site-packages/websockets/legacy/protocol.py", line 1029, in read_message
    frame = await self.read_data_frame(max_size=self.max_size)
  File "/home/runner/work/mysql-router-k8s-operator/mysql-router-k8s-operator/.tox/integration/lib/python3.10/site-packages/websockets/legacy/protocol.py", line 1104, in read_data_frame
    frame = await self.read_frame(max_size)
  File "/home/runner/work/mysql-router-k8s-operator/mysql-router-k8s-operator/.tox/integration/lib/python3.10/site-packages/websockets/legacy/protocol.py", line 1161, in read_frame
    frame = await Frame.read(
  File "/home/runner/work/mysql-router-k8s-operator/mysql-router-k8s-operator/.tox/integration/lib/python3.10/site-packages/websockets/legacy/framing.py", line 68, in read
    data = await reader(2)
  File "/usr/lib/python3.10/asyncio/streams.py", line 708, in readexactly
    await self._wait_for_data('readexactly')
  File "/usr/lib/python3.10/asyncio/streams.py", line 501, in _wait_for_data
    await self._waiter
  File "/usr/lib/python3.10/asyncio/selector_events.py", line 924, in write
    n = self._sock.send(data)
OSError: [Errno 9] Bad file descriptor