[32mINFO    [0m pytest_operator.plugin:plugin.py:790 Model status:

Model  Controller          Cloud/Region        Version  SLA          Timestamp
test   microk8s-localhost  microk8s/localhost  3.4.3    unsupported  02:13:10Z

App                       Version  Status   Scale  Charm                     Channel        Rev  Address         Exposed  Message
data-integrator                    waiting      1  data-integrator           latest/edge     38  10.152.183.21   no       installing agent
mysql-k8s                          waiting      3  mysql-k8s                 8.0/edge       169  10.152.183.126  no       installing agent
mysql-router-k8s                   unknown      1  mysql-router-k8s                           0  10.152.183.46   no       
mysql-test-app            0.0.2    waiting      1  mysql-test-app            latest/edge     46  10.152.183.216  no       installing agent
self-signed-certificates           active       1  self-signed-certificates  latest/stable  155  10.152.183.99   no       

Unit                         Workload     Agent      Address      Ports  Message
data-integrator/0*           blocked      idle       10.1.219.74         Please relate the data-integrator with the desired product
mysql-k8s/0                  maintenance  executing  10.1.219.79         installing charm software
mysql-k8s/1                  maintenance  executing  10.1.219.81         installing charm software
mysql-k8s/2*                 error        idle       10.1.219.80         hook failed: "leader-elected"
mysql-router-k8s/0*          unknown      idle       10.1.219.72         
mysql-test-app/0*            waiting      idle       10.1.219.73         
self-signed-certificates/0*  active       idle       10.1.219.75         

[32mINFO    [0m pytest_operator.plugin:plugin.py:796 Juju error logs:

unit-mysql-k8s-2: 02:13:09 ERROR unit.mysql-k8s/2.juju-log Uncaught exception while in charm code:
Traceback (most recent call last):
  File "/var/lib/juju/agents/unit-mysql-k8s-2/charm/./src/charm.py", line 866, in <module>
    main(MySQLOperatorCharm)
  File "/var/lib/juju/agents/unit-mysql-k8s-2/charm/venv/ops/main.py", line 551, in main
    manager.run()
  File "/var/lib/juju/agents/unit-mysql-k8s-2/charm/venv/ops/main.py", line 530, in run
    self._emit()
  File "/var/lib/juju/agents/unit-mysql-k8s-2/charm/venv/ops/main.py", line 519, in _emit
    _emit_charm_event(self.charm, self.dispatcher.event_name)
  File "/var/lib/juju/agents/unit-mysql-k8s-2/charm/venv/ops/main.py", line 147, in _emit_charm_event
    event_to_emit.emit(*args, **kwargs)
  File "/var/lib/juju/agents/unit-mysql-k8s-2/charm/venv/ops/framework.py", line 348, in emit
    framework._emit(event)
  File "/var/lib/juju/agents/unit-mysql-k8s-2/charm/venv/ops/framework.py", line 860, in _emit
    self._reemit(event_path)
  File "/var/lib/juju/agents/unit-mysql-k8s-2/charm/venv/ops/framework.py", line 950, in _reemit
    custom_handler(event)
  File "/var/lib/juju/agents/unit-mysql-k8s-2/charm/lib/charms/tempo_k8s/v1/charm_tracing.py", line 647, in wrapped_function
    return callable(*args, **kwargs)  # type: ignore
  File "/var/lib/juju/agents/unit-mysql-k8s-2/charm/src/relations/mysql_provider.py", line 211, in _configure_endpoints
    if not relations or not self.charm.unit_initialized:
  File "/var/lib/juju/agents/unit-mysql-k8s-2/charm/lib/charms/mysql/v0/mysql.py", line 634, in unit_initialized
    return self._mysql.cluster_metadata_exists(self.get_unit_address(self.unit))
  File "/var/lib/juju/agents/unit-mysql-k8s-2/charm/lib/charms/tempo_k8s/v1/charm_tracing.py", line 647, in wrapped_function
    return callable(*args, **kwargs)  # type: ignore
  File "/var/lib/juju/agents/unit-mysql-k8s-2/charm/lib/charms/mysql/v0/mysql.py", line 1412, in cluster_metadata_exists
    output = self._run_mysqlsh_script("\n".join(check_cluster_metadata_commands))
  File "/var/lib/juju/agents/unit-mysql-k8s-2/charm/lib/charms/tempo_k8s/v1/charm_tracing.py", line 647, in wrapped_function
    return callable(*args, **kwargs)  # type: ignore
  File "/var/lib/juju/agents/unit-mysql-k8s-2/charm/src/mysql_k8s_helpers.py", line 594, in _run_mysqlsh_script
    self.container.push(path=MYSQLSH_SCRIPT_FILE, source=script)
  File "/var/lib/juju/agents/unit-mysql-k8s-2/charm/venv/ops/model.py", line 2438, in push
    self._pebble.push(
  File "/var/lib/juju/agents/unit-mysql-k8s-2/charm/venv/ops/pebble.py", line 2494, in push
    response = self._request_raw('POST', '/v1/files', None, headers, data)
  File "/var/lib/juju/agents/unit-mysql-k8s-2/charm/venv/ops/pebble.py", line 2048, in _request_raw
    raise ConnectionError(
ops.pebble.ConnectionError: Could not connect to Pebble: socket not found at '/charm/containers/mysql/pebble.socket' (container restarted?)

[32mINFO    [0m pytest_operator.plugin:plugin.py:862 Forgetting main...
[31m[1mERROR   [0m websockets.client:protocol.py:1015 data transfer failed
Traceback (most recent call last):
  File "/home/runner/work/mysql-router-k8s-operator/mysql-router-k8s-operator/.tox/integration/lib/python3.10/site-packages/websockets/legacy/protocol.py", line 959, in transfer_data
    message = await self.read_message()
  File "/home/runner/work/mysql-router-k8s-operator/mysql-router-k8s-operator/.tox/integration/lib/python3.10/site-packages/websockets/legacy/protocol.py", line 1029, in read_message
    frame = await self.read_data_frame(max_size=self.max_size)
  File "/home/runner/work/mysql-router-k8s-operator/mysql-router-k8s-operator/.tox/integration/lib/python3.10/site-packages/websockets/legacy/protocol.py", line 1104, in read_data_frame
    frame = await self.read_frame(max_size)
  File "/home/runner/work/mysql-router-k8s-operator/mysql-router-k8s-operator/.tox/integration/lib/python3.10/site-packages/websockets/legacy/protocol.py", line 1161, in read_frame
    frame = await Frame.read(
  File "/home/runner/work/mysql-router-k8s-operator/mysql-router-k8s-operator/.tox/integration/lib/python3.10/site-packages/websockets/legacy/framing.py", line 68, in read
    data = await reader(2)
  File "/usr/lib/python3.10/asyncio/streams.py", line 708, in readexactly
    await self._wait_for_data('readexactly')
  File "/usr/lib/python3.10/asyncio/streams.py", line 501, in _wait_for_data
    await self._waiter
  File "/usr/lib/python3.10/asyncio/selector_events.py", line 924, in write
    n = self._sock.send(data)
OSError: [Errno 9] Bad file descriptor